Workbook

Sheet LEGGIMI
A1: LISTINO DI ESEMPIO – Preventivatore LCM Marchioni (prototipo)
A2: Tutti i valori sono INDICATIVI e servono solo a far funzionare la demo: vanno sostituiti con i dati reali di LCM.
A4: Come si legge
A5: • Testo BLU = dato da inserire/modificare. • Testo NERO su fondo grigio = formula, non toccare.
A6: • La riga 1 di ogni foglio contiene i nomi colonna letti dal preventivatore: non rinominarli.
A7: • Le percentuali sono scritte come frazioni (0,20 = 20%).
A9: Fogli
A10: Parametri – spese generali, ricarichi per tipo cliente, IVA, costo operatore.
A11: Fornitori – anagrafica fornitori materiale.
A12: Materiali – una riga per materiale + spessore: €/m², formato lastra, sfrido %, classe.
A13: Classi – coefficiente di difficoltà per classe di materiale (marmo = 1,00 riferimento).
A14: Spessori – coefficiente per spessore (2 cm = 1,00 riferimento).
... A28: N_PZ = numero pezzi (N, raddoppia se H>0) · N = numero inserito · MANUALE = il coefficiente è la quantità di default

Sheet Parametri
A1: Chiave | B1: Valore | C1: Descrizione
A2: Spese_generali | B2: 0.18 | C2: Spese generali d'impresa sul costo diretto (ufficio, affitto, assicurazioni...)
A3: Ricarico_Privato | B3: 0.4 | C3: Ricarico sul costo pieno – cliente privato
A4: Ricarico_Professionista | B4: 0.25 | C4: Ricarico sul costo pieno – posatori, imprese, architetti
A5: Ricarico_Estero | B5: 0.3 | C5: Ricarico sul costo pieno – clienti esteri
A6: IVA | B6: 0.22 | C6: Aliquota IVA di riserva (se manca il foglio Aliquote_IVA)
A7: IVA_Privato | B7: IVA22 | C7: Regime IVA proposto per cliente Privato (codice del foglio Aliquote_IVA)
A8: IVA_Professionista | B8: IVA22 | C8: Regime IVA proposto per Professionista / P.IVA
A9: IVA_Estero | B9: ESENTE_EXP | C9: Regime IVA proposto per cliente Estero
A10: Costo_operatore_h | B10: 32 | C10: Costo aziendale orario di un operatore (€/h)
A11: Arrotondamento | B11: 5 | C11: Arrotonda il prezzo finale al multiplo di (€). 0 = nessun arrotondamento
A12: Validita_giorni | B12: 30 | C12: Validità dell'offerta (giorni)
A13: Ragione_sociale | B13: L.C.M. Marchioni Srl | C13: Intestazione offerta
A14: Testo_trasporto_cliente | B14: Trasporto a carico del cliente | C14: Dicitura in offerta quando il trasporto non è incluso
A15: Note_offerta | B15: Misure da confermare con rilievo. Venature e tonalità dei materiali naturali possono variare rispetto ai campioni. | C15: Note standard in fondo all'offerta

Sheet Fornitori
A1: Codice | B1: Nome | C1: Sede | D1: Note
A2: F01 | B2: Fornitore Marmi Apuani (esempio) | C2: Carrara (MS) | D2: Listino 2026 – Excel
A3: F02 | B3: Fornitore Graniti Import (esempio) | C3: Verona (VR) | D3: Listino 2026 – PDF
A4: F03 | B4: Fornitore Sinterizzati (esempio) | C4: Sassuolo (MO) | D4: Listino 2026 – Excel
A5: F04 | B5: Fornitore Quarzi & Agglomerati (esempio) | C5: Vicenza (VI) | D5: Listino 2026 – Excel

Sheet Classi
A1: Classe | B1: Descrizione | C1: Coeff_lavorazione | D1: Note
A2: MARMO | B2: Marmo / calcare | C2: 1 | D2: Riferimento
A3: GRANITO | B3: Granito | C3: 1.6 | D3: Più duro: taglio e lucidatura più lenti, più usura utensili
A4: QUARZITE | B4: Quarzite | C4: 2 | D4: Molto dura
A5: AGGLOMERATO | B5: Quarzo agglomerato | C5: 1.3
A6: SINTERIZZATO | B6: Sinterizzato / gres grande lastra (Laminam, Kerlite...) | C6: 1.8 | D6: Fragile: velocità ridotte, più scarti
A7: CERAMICA | B7: Gres porcellanato spessorato | C7: 1.5

Sheet Spessori
A1: Spessore_cm | B1: Coeff_spessore
A2: 0.6 | B2: 0.7
A3: 1.2 | B3: 0.85
A4: 2 | B4: 1
A5: 3 | B5: 1.3
A6: 4 | B6: 1.6
A7: 5 | B7: 1.9

Sheet Materiali
A1: Codice | B1: Materiale | C1: Classe | D1: Fornitore | E1: Spessore_cm | F1: Prezzo_m2 | G1: Lastra_L_cm | H1: Lastra_H_cm | I1: Sfrido | J1: Finitura_std | K1: Lastra_m2 | L1: Prezzo_lastra
A2: CARR-2 | B2: Bianco Carrara C | C2: MARMO | D2: F01 | E2: 2 | F2: 95 | G2: 300 | H2: 160 | I2: 0.2 | J2: Lucido | K2: =G2*H2/10000 -> 4.8 | L2: =F2*G2*H2/10000 -> 456
A3: CARR-3 | B3: Bianco Carrara C | C3: MARMO | D3: F01 | E3: 3 | F3: 130 | G3: 300 | H3: 160 | I3: 0.2 | J3: Lucido | K3: =G3*H3/10000 -> 4.8 | L3: =F3*G3*H3/10000 -> 624
A4: BOTT-2 | B4: Botticino Classico | C4: MARMO | D4: F01 | E4: 2 | F4: 70 | G4: 290 | H4: 150 | I4: 0.2 | J4: Lucido | K4: =G4*H4/10000 -> 4.35 | L4: =F4*G4*H4/10000 -> 304.5
A5: BOTT-3 | B5: Botticino Classico | C5: MARMO | D5: F01 | E5: 3 | F5: 95 | G5: 290 | H5: 150 | I5: 0.2 | J5: Lucido | K5: =G5*H5/10000 -> 4.35 | L5: =F5*G5*H5/10000 -> 413.25
A6: MARQ-2 | B6: Nero Marquinia | C6: MARMO | D6: F01 | E6: 2 | F6: 140 | G6: 280 | H6: 150 | I6: 0.25 | J6: Lucido | K6: =G6*H6/10000 -> 4.2 | L6: =F6*G6*H6/10000 -> 588
A7: NASS-2 | B7: Nero Assoluto | C7: GRANITO | D7: F02 | E7: 2 | F7: 120 | G7: 300 | H7: 180 | I7: 0.15 | J7: Lucido | K7: =G7*H7/10000 -> 5.4 | L7: =F7*G7*H7/10000 -> 648
A8: NASS-3 | B8: Nero Assoluto | C8: GRANITO | D8: F02 | E8: 3 | F8: 165 | G8: 300 | H8: 180 | I8: 0.15 | J8: Lucido | K8: =G8*H8/10000 -> 5.4 | L8: =F8*G8*H8/10000 -> 891
A9: BSAR-2 | B9: Bianco Sardo | C9: GRANITO | D9: F02 | E9: 2 | F9: 55 | G9: 300 | H9: 180 | I9: 0.15 | J9: Lucido | K9: =G9*H9/10000 -> 5.4 | L9: =F9*G9*H9/10000 -> 297
A10: BSAR-3 | B10: Bianco Sardo | C10: GRANITO | D10: F02 | E10: 3 | F10: 75 | G10: 300 | H10: 180 | I10: 0.15 | J10: Lucido | K10: =G10*H10/10000 -> 5.4 | L10: =F10*G10*H10/10000 -> 405
A11: RBET-3 | B11: Rosa Beta | C11: GRANITO | D11: F02 | E11: 3 | F11: 80 | G11: 300 | H11: 180 | I11: 0.15 | J11: Lucido | K11: =G11*H11/10000 -> 5.4 | L11: =F11*G11*H11/10000 -> 432
A12: TAJM-2 | B12: Quarzite Taj Mahal | C12: QUARZITE | D12: F02 | E12: 2 | F12: 260 | G12: 300 | H12: 190 | I12: 0.25 | J12: Lucido | K12: =G12*H12/10000 -> 5.7 | L12: =F12*G12*H12/10000 -> 1482
A13: QBIA-2 | B13: Quarzo Bianco Assoluto | C13: AGGLOMERATO | D13: F04 | E13: 2 | F13: 120 | G13: 306 | H13: 140 | I13: 0.15 | J13: Lucido | K13: =G13*H13/10000 -> 4.284 | L13: =F13*G13*H13/10000 -> 514.08
... A17: GRES-2 | B17: Gres porcellanato pietra grigia | C17: CERAMICA | D17: F03 | E17: 2 | F17: 65 | G17: 120 | H17: 60 | I17: 0.1 | J17: Strutturato | K17: =G17*H17/10000 -> 0.72 | L17: =F17*G17*H17/10000 -> 46.8

Sheet Risorse
A1: Codice | B1: Risorsa | C1: Valore_acquisto | D1: Anni_ammortamento | E1: Ore_annue | F1: Potenza_kW | G1: Costo_kWh | H1: Utensili_h | I1: Manutenzione_anno | J1: N_operatori | K1: Ammortamento_h | L1: Energia_h | M1: Manutenzione_h | N1: Costo_macchina_h | O1: Costo_operatore_h | P1: Costo_orario
A2: FRESA | B2: Fresa a ponte (taglio) | C2: 180000 | D2: 10 | E2: 1600 | F2: 22 | G2: 0.25 | H2: 6 | I2: 4000 | J2: 1 | K2: =IFERROR(C2/D2/E2,0) -> 11.25 | L2: =F2*G2 -> 5.5 | M2: =IFERROR(I2/E2,0) -> 2.5 | N2: =K2+L2+H2+M2 -> 25.25 | O2: =J2*INDEX(Parametri!$B:$B,MATCH("Costo_operatore_h",Parametri!$A:$A,0)) -> 32 | P2: =N2+O2 -> 57.25
A3: CNC | B3: Centro di lavoro CNC 5 assi | C3: 350000 | D3: 10 | E3: 1600 | F3: 30 | G3: 0.25 | H3: 10 | I3: 8000 | J3: 1 | K3: =IFERROR(C3/D3/E3,0) -> 21.875 | L3: =F3*G3 -> 7.5 | M3: =IFERROR(I3/E3,0) -> 5 | N3: =K3+L3+H3+M3 -> 44.375 | O3: =J3*INDEX(Parametri!$B:$B,MATCH("Costo_operatore_h",Parametri!$A:$A,0)) -> 32 | P3: =N3+O3 -> 76.375
A4: WJ | B4: Waterjet | C4: 250000 | D4: 10 | E4: 1400 | F4: 37 | G4: 0.25 | H4: 18 | I4: 10000 | J4: 0.5 | K4: =IFERROR(C4/D4/E4,0) -> 17.857143 | L4: =F4*G4 -> 9.25 | M4: =IFERROR(I4/E4,0) -> 7.1428571 | N4: =K4+L4+H4+M4 -> 52.25 | O4: =J4*INDEX(Parametri!$B:$B,MATCH("Costo_operatore_h",Parametri!$A:$A,0)) -> 16 | P4: =N4+O4 -> 68.25
A5: COSTE | B5: Lucidacoste automatica | C5: 90000 | D5: 10 | E5: 1600 | F5: 15 | G5: 0.25 | H5: 4 | I5: 2500 | J5: 0.5 | K5: =IFERROR(C5/D5/E5,0) -> 5.625 | L5: =F5*G5 -> 3.75 | M5: =IFERROR(I5/E5,0) -> 1.5625 | N5: =K5+L5+H5+M5 -> 14.9375 | O5: =J5*INDEX(Parametri!$B:$B,MATCH("Costo_operatore_h",Parametri!$A:$A,0)) -> 16 | P5: =N5+O5 -> 30.9375
A6: LUCID | B6: Levigatrice / lucidatrice superfici | C6: 120000 | D6: 10 | E6: 1600 | F6: 20 | G6: 0.25 | H6: 5 | I6: 3000 | J6: 0.5 | K6: =IFERROR(C6/D6/E6,0) -> 7.5 | L6: =F6*G6 -> 5 | M6: =IFERROR(I6/E6,0) -> 1.875 | N6: =K6+L6+H6+M6 -> 19.375 | O6: =J6*INDEX(Parametri!$B:$B,MATCH("Costo_operatore_h",Parametri!$A:$A,0)) -> 16 | P6: =N6+O6 -> 35.375
A7: BANCO | B7: Banco manuale (utensili elettrici) | C7: 5000 | D7: 5 | E7: 1600 | F7: 3 | G7: 0.25 | H7: 2 | I7: 300 | J7: 1 | K7: =IFERROR(C7/D7/E7,0) -> 0.625 | L7: =F7*G7 -> 0.75 | M7: =IFERROR(I7/E7,0) -> 0.1875 | N7: =K7+L7+H7+M7 -> 3.5625 | O7: =J7*INDEX(Parametri!$B:$B,MATCH("Costo_operatore_h",Parametri!$A:$A,0)) -> 32 | P7: =N7+O7 -> 35.5625
A8: IMBALLO | B8: Postazione imballo | C8: 3000 | D8: 5 | E8: 1600 | F8: 0 | G8: 0.25 | H8: 0 | I8: 100 | J8: 1 | K8: =IFERROR(C8/D8/E8,0) -> 0.375 | L8: =F8*G8 -> 0 | M8: =IFERROR(I8/E8,0) -> 0.0625 | N8: =K8+L8+H8+M8 -> 0.4375 | O8: =J8*INDEX(Parametri!$B:$B,MATCH("Costo_operatore_h",Parametri!$A:$A,0)) -> 32 | P8: =N8+O8 -> 32.4375

Sheet Lavorazioni
A1: Codice | B1: Lavorazione | C1: Categoria | D1: UM | E1: Risorsa | F1: Velocita_UM_min | G1: Setup_min | H1: Applica_coeff_classe | I1: Applica_coeff_spessore | J1: Note | K1: Tempo_min_per_UM
A2: TAGLIO | B2: Taglio a misura | C2: TAGLIO | D2: ml | E2: FRESA | F2: 2 | G2: 5 | H2: SI | I2: SI | J2: Rif. 2 ml/min su marmo 2 cm | K2: =IFERROR(1/F2,0) -> 0.5
A3: TAGLIO45 | B3: Taglio a 45° (giunto jolly) | C3: TAGLIO | D3: ml | E3: FRESA | F3: 0.8 | G3: 5 | H3: SI | I3: SI | K3: =IFERROR(1/F3,0) -> 1.25
A4: SAGOMA | B4: Sagomatura / tagli curvi | C4: TAGLIO | D4: ml | E4: WJ | F4: 0.3 | G4: 10 | H4: SI | I4: SI | K4: =IFERROR(1/F4,0) -> 3.3333333
A5: FILO | B5: Filo lucido costa dritta | C5: BORDO | D5: ml | E5: COSTE | F5: 1 | G5: 3 | H5: SI | I5: SI | K5: =IFERROR(1/F5,0) -> 1
A6: BISELLO | B6: Bisello / smusso | C6: BORDO | D6: ml | E6: COSTE | F6: 1.2 | G6: 3 | H6: SI | I6: SI | K6: =IFERROR(1/F6,0) -> 0.83333333
A7: TORO | B7: Toro / mezzo toro | C7: BORDO | D7: ml | E7: CNC | F7: 0.4 | G7: 10 | H7: SI | I7: SI | K7: =IFERROR(1/F7,0) -> 2.5
A8: INGROSSO | B8: Ingrossamento incollato (veletta) | C8: BORDO | D8: ml | E8: BANCO | F8: 0.15 | G8: 0 | H8: NO | I8: NO | J8: ≈ 7 min/ml | K8: =IFERROR(1/F8,0) -> 6.6666667
A9: GOCCIOL | B9: Gocciolatoio | C9: BORDO | D9: ml | E9: FRESA | F9: 1.5 | G9: 3 | H9: SI | I9: NO | K9: =IFERROR(1/F9,0) -> 0.66666667
A10: ANTISCIV | B10: Scanalature antiscivolo | C10: BORDO | D10: ml | E10: CNC | F10: 0.8 | G10: 5 | H10: SI | I10: NO | K10: =IFERROR(1/F10,0) -> 1.25
A11: FORO_SOTTO | B11: Foro lavello sottotop con filo lucido | C11: FORI | D11: pz | E11: CNC | F11: 0.025 | G11: 0 | H11: SI | I11: SI | J11: ≈ 40 min/pz | K11: =IFERROR(1/F11,0) -> 40
A12: FORO_APP | B12: Foro lavello/vasca da appoggio | C12: FORI | D12: pz | E12: CNC | F12: 0.05 | G12: 0 | H12: SI | I12: SI | J12: ≈ 20 min/pz | K12: =IFERROR(1/F12,0) -> 20
A13: FORO_PC | B13: Foro piano cottura | C13: FORI | D13: pz | E13: WJ | F13: 0.05 | G13: 0 | H13: SI | I13: SI | J13: ≈ 20 min/pz | K13: =IFERROR(1/F13,0) -> 20
A14: FORO_RUB | B14: Foro rubinetto / accessori | C14: FORI | D14: pz | E14: CNC | F14: 0.33 | G14: 0 | H14: SI | I14: NO | J14: ≈ 3 min/pz | K14: =IFERROR(1/F14,0) -> 3.030303
A15: LUCIDATURA | B15: Lucidatura superficie | C15: FINITURA | D15: m2 | E15: LUCID | F15: 0.15 | G15: 5 | H15: SI | I15: NO | K15: =IFERROR(1/F15,0) -> 6.6666667
A16: LEVIGATURA | B16: Levigatura (opaco) | C16: FINITURA | D16: m2 | E16: LUCID | F16: 0.2 | G16: 5 | H16: SI | I16: NO | K16: =IFERROR(1/F16,0) -> 5
A17: SPAZZOLAT | B17: Spazzolatura | C17: FINITURA | D17: m2 | E17: LUCID | F17: 0.15 | G17: 5 | H17: SI | I17: NO | K17: =IFERROR(1/F17,0) -> 6.6666667
A18: FIAMMAT | B18: Fiammatura (solo graniti) | C18: FINITURA | D18: m2 | E18: BANCO | F18: 0.1 | G18: 5 | H18: NO | I18: NO | K18: =IFERROR(1/F18,0) -> 10
A19: RESINAT | B19: Resinatura / trattamento protettivo | C19: FINITURA | D19: m2 | E19: BANCO | F19: 0.25 | G19: 0 | H19: NO | I19: NO | K19: =IFERROR(1/F19,0) -> 4
A20: MONTAGGIO | B20: Assemblaggio / incollaggio a banco | C20: MONTAGGIO | D20: pz | E20: BANCO | F20: 0.033 | G20: 0 | H20: NO | I20: NO | J20: ≈ 30 min/pz | K20: =IFERROR(1/F20,0) -> 30.30303
A21: MOVIM | B21: Movimentazione e carico lastra | C21: ALTRO | D21: pz | E21: BANCO | F21: 0.2 | G21: 0 | H21: NO | I21: NO | J21: ≈ 5 min/pz | K21: =IFERROR(1/F21,0) -> 5
A22: IMBALLO_MO | B22: Imballo (manodopera) | C22: ALTRO | D22: m2 | E22: IMBALLO | F22: 0.5 | G22: 5 | H22: NO | I22: NO | J22: ≈ 2 min/m² | K22: =IFERROR(1/F22,0) -> 2

Sheet Modelli
A1: Codice | B1: Modello | C1: Label_L | D1: Label_P | E1: Label_H | F1: Label_N | G1: Default_L | H1: Default_P | I1: Default_H | J1: Default_N | K1: Sfrido_override
A2: TOP_CUCINA | B2: Top cucina | C2: Lunghezza (cm) | D2: Profondità (cm) | E2: Altezza alzatina (cm, 0 = no) | F2: N. pezzi | G2: 300 | H2: 62 | I2: 8 | J2: 1
A3: TOP_BAGNO | B3: Top bagno | C3: Lunghezza (cm) | D3: Profondità (cm) | E3: Altezza veletta/alzatina (cm, 0 = no) | F3: N. pezzi | G3: 120 | H3: 50 | I3: 0 | J3: 1
A4: SCALA | B4: Scala (pedate + alzate) | C4: Larghezza gradino (cm) | D4: Pedata (cm) | E4: Alzata (cm, 0 = senza alzate) | F4: N. gradini | G4: 100 | H4: 30 | I4: 17 | J4: 14 | K4: 0.25
A5: DAVANZALE | B5: Davanzale / soglia | C5: Lunghezza (cm) | D5: Profondità (cm) | E5: — | F5: N. pezzi | G5: 120 | H5: 30 | I5: 0 | J5: 4
A6: BANCONE | B6: Bancone (piano + frontale a 45°) | C6: Lunghezza (cm) | D6: Profondità piano (cm) | E6: Altezza frontale (cm) | F6: N. banconi | G6: 250 | H6: 60 | I6: 110 | J6: 1
A7: RIVESTIM | B7: Rivestimento / pavimento a misura | C7: Lunghezza (cm) | D7: Larghezza (cm) | E7: — | F7: N. lastre/pezzi | G7: 60 | H7: 60 | I7: 0 | J7: 20
A8: LIBERO | B8: Pezzo libero | C8: Lunghezza (cm) | D8: Larghezza (cm) | E8: Altezza 2° elemento (cm) | F8: N. pezzi | G8: 100 | H8: 50 | I8: 0 | J8: 1

Sheet Modelli_Lavorazioni
A1: Modello | B1: Lavorazione | C1: Base | D1: Coeff | E1: Attiva_default | F1: Nota
A2: TOP_CUCINA | B2: TAGLIO | C2: ML_PERIM | D2: 1 | E2: SI | F2: Taglio del piano
A3: TOP_CUCINA | B3: FILO | C3: ML_FRONTE | D3: 1 | E3: SI | F3: Filo lucido sul fronte
A4: TOP_CUCINA | B4: FILO | C4: ML_LATI | D4: 0.5 | E4: NO | F4: Testate a vista (una per lato)
A5: TOP_CUCINA | B5: FORO_SOTTO | C5: MANUALE | D5: 1 | E5: SI | F5: Lavello sottotop
A6: TOP_CUCINA | B6: FORO_PC | C6: MANUALE | D6: 1 | E6: SI | F6: Piano cottura
A7: TOP_CUCINA | B7: FORO_RUB | C7: MANUALE | D7: 1 | E7: SI | F7: Rubinetto
A8: TOP_CUCINA | B8: TAGLIO | C8: ML_PERIM_H | D8: 1 | E8: SI | F8: Taglio alzatina
A9: TOP_CUCINA | B9: FILO | C9: ML_ALZ | D9: 1 | E9: SI | F9: Filo lucido alzatina
A10: TOP_CUCINA | B10: MOVIM | C10: N_PZ | D10: 1 | E10: SI
A11: TOP_CUCINA | B11: IMBALLO_MO | C11: AREA | D11: 1 | E11: SI
A12: TOP_BAGNO | B12: TAGLIO | C12: ML_PERIM | D12: 1 | E12: SI
A13: TOP_BAGNO | B13: FILO | C13: ML_FRONTE | D13: 1 | E13: SI
A14: TOP_BAGNO | B14: FILO | C14: ML_LATI | D14: 1 | E14: NO | F14: Lati a vista
A15: TOP_BAGNO | B15: INGROSSO | C15: ML_FRONTE | D15: 1 | E15: NO | F15: Veletta ingrossata
A16: TOP_BAGNO | B16: FORO_SOTTO | C16: MANUALE | D16: 1 | E16: SI
A17: TOP_BAGNO | B17: FORO_RUB | C17: MANUALE | D17: 1 | E17: SI
A18: TOP_BAGNO | B18: TAGLIO | C18: ML_PERIM_H | D18: 1 | E18: SI | F18: Alzatina/veletta
A19: TOP_BAGNO | B19: MOVIM | C19: N_PZ | D19: 1 | E19: SI
A20: TOP_BAGNO | B20: IMBALLO_MO | C20: AREA | D20: 1 | E20: SI
A21: SCALA | B21: TAGLIO | C21: ML_PERIM | D21: 1 | E21: SI | F21: Pedate
A22: SCALA | B22: TAGLIO | C22: ML_PERIM_H | D22: 1 | E22: SI | F22: Alzate
A23: SCALA | B23: TORO | C23: ML_FRONTE | D23: 1 | E23: SI | F23: Fronte pedata
A24: SCALA | B24: BISELLO | C24: ML_FRONTE | D24: 1 | E24: NO | F24: Alternativa al toro
A25: SCALA | B25: FILO | C25: ML_LATI | D25: 0.5 | E25: NO | F25: Lato a vista (scala a giorno)
A26: SCALA | B26: ANTISCIV | C26: ML_FRONTE | D26: 2 | E26: NO | F26: 2 righe per gradino
A27: SCALA | B27: MOVIM | C27: N_PZ | D27: 1 | E27: SI
A28: SCALA | B28: IMBALLO_MO | C28: AREA | D28: 1 | E28: SI
A29: DAVANZALE | B29: TAGLIO | C29: ML_PERIM | D29: 1 | E29: SI
A30: DAVANZALE | B30: FILO | C30: ML_FRONTE | D30: 1 | E30: SI
A31: DAVANZALE | B31: FILO | C31: ML_LATI | D31: 1 | E31: SI | F31: Testate
A32: DAVANZALE | B32: GOCCIOL | C32: ML_FRONTE | D32: 1 | E32: SI
A33: DAVANZALE | B33: MOVIM | C33: N_PZ | D33: 1 | E33: SI
A34: DAVANZALE | B34: IMBALLO_MO | C34: AREA | D34: 1 | E34: SI
A35: BANCONE | B35: TAGLIO | C35: ML_PERIM | D35: 1 | E35: SI | F35: Piano
A36: BANCONE | B36: TAGLIO | C36: ML_PERIM_H | D36: 1 | E36: SI | F36: Frontale
A37: BANCONE | B37: TAGLIO45 | C37: ML_FRONTE | D37: 2 | E37: SI | F37: Giunto piano-frontale
A38: BANCONE | B38: FILO | C38: ML_LATI | D38: 1 | E38: SI
A39: BANCONE | B39: MONTAGGIO | C39: N | D39: 1 | E39: SI | F39: Incollaggio a banco
A40: BANCONE | B40: MOVIM | C40: N_PZ | D40: 1 | E40: SI
...

Sheet Accessori
A1: Codice | B1: Voce | C1: UM | D1: Costo_unitario | E1: Base_default | F1: Attivo_default | G1: Visibile_cliente | H1: Note
A2: IMB_PALLET | B2: Imballo pallet + angolari + film | C2: m2 | D2: 6 | E2: M2_TOT | F2: SI | G2: NO | H2: Costo interno, ripartito sui prodotti
A3: IMB_CASSA | B3: Cassa in legno (spedizione/estero) | C3: pz | D3: 85 | E3: 0 | F3: NO | G3: NO | H3: Costo interno, ripartito sui prodotti
A4: SILICONE | B4: Sigillature e materiale di consumo | C4: forfait | D4: 25 | E4: 0 | F4: NO | G4: NO | H4: Costo interno, ripartito sui prodotti
A5: RILIEVO | B5: Rilievo misure in cantiere | C5: forfait | D5: 70 | E5: 1 | F5: NO | G5: SI | H5: Riga visibile in offerta
A6: POSA_M2 | B6: Posa in opera | C6: m2 | D6: 45 | E6: M2_TOT | F6: NO | G6: SI | H6: LCM fa poca posa
A7: POSA_H | B7: Assistenza / posa a ore | C7: h | D7: 38 | E7: 0 | F7: NO | G7: SI

Sheet Aliquote_IVA
A1: Codice | B1: Descrizione | C1: Aliquota | D1: Dicitura_offerta
A2: IVA22 | B2: IVA 22% ordinaria | C2: 0.22
A3: IVA10 | B3: IVA 10% agevolata (recupero edilizio) | C3: 0.1 | D3: Aliquota agevolata 10% su dichiarazione del cliente; requisiti da verificare.
A4: IVA4 | B4: IVA 4% agevolata | C4: 0.04 | D4: Aliquota agevolata 4% su dichiarazione del cliente; requisiti da verificare.
A5: ESENTE_EXP | B5: Non imponibile – esportazione extra UE | C5: 0 | D5: Operazione non imponibile IVA ai sensi dell'art. 8 DPR 633/72.
A6: ESENTE_UE | B6: Non imponibile – cessione intracomunitaria | C6: 0 | D6: Operazione non imponibile IVA ai sensi dell'art. 41 DL 331/93.
A7: REVERSE | B7: Reverse charge | C7: 0 | D7: Operazione soggetta a inversione contabile (reverse charge).
